<?xml version="1.0" encoding="UTF-8"?>
<testng-results skipped="0" failed="1" total="2" passed="1">
  <reporter-output>
  </reporter-output>
  <suite name="Default suite" duration-ms="33141" started-at="2015-05-21T14:14:15Z" finished-at="2015-05-21T14:14:48Z">
    <groups>
    </groups>
    <test name="Default test" duration-ms="33141" started-at="2015-05-21T14:14:15Z" finished-at="2015-05-21T14:14:48Z">
      <class name="javarush_test.JavaPWTest">
        <test-method status="PASS" signature="startup()[pri:0, instance:javarush_test.JavaPWTest@6debcae2]" name="startup" is-config="true" duration-ms="5608" started-at="2015-05-21T17:14:15Z" finished-at="2015-05-21T17:14:21Z">
          <reporter-output>
          </reporter-output>
        </test-method> <!-- startup -->
        <test-method status="PASS" signature="PWTest()[pri:0, instance:javarush_test.JavaPWTest@6debcae2]" name="PWTest" duration-ms="27384" started-at="2015-05-21T17:14:21Z" finished-at="2015-05-21T17:14:48Z">
          <reporter-output>
          </reporter-output>
        </test-method> <!-- PWTest -->
        <test-method status="FAIL" signature="PWTest2()[pri:0, instance:javarush_test.JavaPWTest@6debcae2]" name="PWTest2" duration-ms="1" started-at="2015-05-21T17:14:48Z" finished-at="2015-05-21T17:14:48Z">
          <exception class="java.lang.AssertionError">
            <message>
              <![CDATA[expected [null] but found [eWhljfPq/hBHM@1a]]]>
            </message>
            <full-stacktrace>
              <![CDATA[java.lang.AssertionError: expected [null] but found [eWhljfPq/hBHM@1a]
	at org.testng.Assert.fail(Assert.java:94)
	at org.testng.Assert.failNotEquals(Assert.java:496)
	at org.testng.Assert.assertEquals(Assert.java:116)
	at org.testng.Assert.assertEquals(Assert.java:178)
	at org.testng.Assert.assertEquals(Assert.java:188)
	at javarush_test.JavaPWTest.PWTest2(JavaPWTest.java:93)
	at sun.reflect.NativeMethodAccessorImpl.invoke0(Native Method)
	at sun.reflect.NativeMethodAccessorImpl.invoke(Unknown Source)
	at sun.reflect.DelegatingMethodAccessorImpl.invoke(Unknown Source)
	at java.lang.reflect.Method.invoke(Unknown Source)
	at org.testng.internal.MethodInvocationHelper.invokeMethod(MethodInvocationHelper.java:85)
	at org.testng.internal.Invoker.invokeMethod(Invoker.java:659)
	at org.testng.internal.Invoker.invokeTestMethod(Invoker.java:845)
	at org.testng.internal.Invoker.invokeTestMethods(Invoker.java:1153)
	at org.testng.internal.TestMethodWorker.invokeTestMethods(TestMethodWorker.java:124)
	at org.testng.internal.TestMethodWorker.run(TestMethodWorker.java:108)
	at org.testng.TestRunner.privateRun(TestRunner.java:771)
	at org.testng.TestRunner.run(TestRunner.java:621)
	at org.testng.SuiteRunner.runTest(SuiteRunner.java:357)
	at org.testng.SuiteRunner.runSequentially(SuiteRunner.java:352)
	at org.testng.SuiteRunner.privateRun(SuiteRunner.java:310)
	at org.testng.SuiteRunner.run(SuiteRunner.java:259)
	at org.testng.SuiteRunnerWorker.runSuite(SuiteRunnerWorker.java:52)
	at org.testng.SuiteRunnerWorker.run(SuiteRunnerWorker.java:86)
	at org.testng.TestNG.runSuitesSequentially(TestNG.java:1199)
	at org.testng.TestNG.runSuitesLocally(TestNG.java:1124)
	at org.testng.TestNG.run(TestNG.java:1032)
	at org.testng.remote.RemoteTestNG.run(RemoteTestNG.java:111)
	at org.testng.remote.RemoteTestNG.initAndRun(RemoteTestNG.java:204)
	at org.testng.remote.RemoteTestNG.main(RemoteTestNG.java:175)
]]>
            </full-stacktrace>
          </exception> <!-- java.lang.AssertionError -->
          <reporter-output>
          </reporter-output>
        </test-method> <!-- PWTest2 -->
        <test-method status="PASS" signature="teardown()[pri:0, instance:javarush_test.JavaPWTest@6debcae2]" name="teardown" is-config="true" duration-ms="134" started-at="2015-05-21T17:14:48Z" finished-at="2015-05-21T17:14:48Z">
          <reporter-output>
          </reporter-output>
        </test-method> <!-- teardown -->
      </class> <!-- javarush_test.JavaPWTest -->
    </test> <!-- Default test -->
  </suite> <!-- Default suite -->
</testng-results>
